Workbook

Sheet Sheet1
A2: Business_Unit_17 | B2: (All)
A4: Row Labels | B4: Sum of Increment_17 | C4: Sum of Salary_17
A5: 0 | B5: 0 | C5: 0
A6: Administration | B6: 30500 | C6: 507500
A7: Audit | B7: 33000 | C7: 391000
A8: Civil | B8: 40000 | C8: 270000
A9: Commercial | B9: 134000 | C9: 1115000
A10: Export Import Audit | B10: 20000 | C10: 120000
A11: Finance & Accounts | B11: 59000 | C11: 844000
A12: Import | B12: 11000 | C12: 125000
A13: Inactive | B13: 0 | C13: 0
A14: Information Technology | B14: 11000 | C14: 143000
A15: Marketing & Sales | B15: 60000 | C15: 648000
A16: Procurement | B16: 30000 | C16: 344000
A17: Transport | B17: 6000 | C17: 86000
... A19: Grand Total | B19: 439500 | C19: 4645500

Sheet DataBase
A1: SL | B1: ID | C1: Name | D1: DOJ | E1: Increment_16 | F1: Emp_Status | G1: Business_Unit_17 | H1: Department_17 | I1: Position_17 | J1: Increment_17 | K1: Promotion_17 | L1: Salary_17 | M1: Remarks_17 | N1: Emp_Status | O1: Business_Unit_18 | P1: Department_18 | Q1: Position_18 | R1: Previous Salary_18 | S1: Increment_18 | T1: Promotion_18 | U1: Perc_18 | V1: Salary_18 | W1: Remarks_18 | X1: Employment | Y1: Business_Unit_20 | Z1: Department_20 | AA1: Position_20 | AB1: Previous Salary_20 | AC1: Increment_20 | AD1: Promotion_20 | AE1: Perc_20 | AF1: Salary_20 | AG1: Remarks_20
B2: 10062011 | C2: Md. Kamruzzaman | E2: 9000 | F2: Active | G2: BTL/KYL | H2: Marketing & Sales | I2: Manager | J2: 10000 | L2: 102000 | N2: Active | O2: BTL/KYL | P2: Marketing & Sales | Q2: Head of Marketing & Sales | R2: =V2-S2 -> 102000 | S2: 48000 | U2: =S2/R2 -> 0.47058824 | V2: =L2+S2 -> 150000 | W2: AE: 25k, SP: 23k | X2: Active | Y2: BTL/KYL | Z2: Marketing & Sales | AA2: Head of Marketing | AB2: =AF2-AC2 -> 150000 | AC2: 25000 | AE2: =AC2/AB2 -> 0.16666667 | AF2: =V2+AC2 -> 175000
B3: 20042012 | C3: Mohammed Nurul Akter Chowdhury | E3: 5000 | F3: Active | G3: BTL/KYL | H3: Marketing & Sales | I3: Manager | J3: 10000 | L3: 100000 | N3: Active | O3: BTL/KYL | P3: Marketing & Sales | Q3: Head of Marketing (Rotor) | R3: =V3-S3 -> 100000 | S3: 20000 | U3: =S3/R3 -> 0.2 | V3: =L3+S3 -> 120000 | X3: Active | Y3: BTL/KYL | Z3: Marketing & Sales | AA3: Head of Marketing - Woven | AB3: =AF3-AC3 -> 120000 | AC3: 25000 | AE3: =AC3/AB3 -> 0.20833333 | AF3: =V3+AC3 -> 145000
B4: 10042008 | C4: Liton Apu Biswas | E4: 3000 | F4: Active | G4: BTL/KYL | H4: Marketing & Sales | I4: Manager | J4: 10000 | L4: 100000 | N4: Active | O4: BTL/KYL | P4: Marketing & Sales | Q4: Head of Marketing (North Zone) | R4: =V4-S4 -> 100000 | S4: 20000 | U4: =S4/R4 -> 0.2 | V4: =L4+S4 -> 120000 | X4: Active | Y4: BTL/KYL | Z4: Marketing & Sales | AA4: Head of Marketing - North | AB4: =AF4-AC4 -> 120000 | AC4: 25000 | AE4: =AC4/AB4 -> 0.20833333 | AF4: =V4+AC4 -> 145000
B5: 10052012 | C5: Md. Abdul Maleque | E5: 10000 | F5: Active | G5: BTL/KYL | H5: Marketing & Sales | I5: Manager | J5: 10000 | L5: 90000 | N5: Active | O5: BTL/KYL | P5: Marketing & Sales | Q5: Head of Marketing (Middle Zone) | R5: =V5-S5 -> 90000 | S5: 20000 | U5: =S5/R5 -> 0.22222222 | V5: =L5+S5 -> 110000 | X5: Active | Y5: BTL/KYL | Z5: Marketing & Sales | AA5: Head of Marketing - Middle | AB5: =AF5-AC5 -> 110000 | AC5: 40000 | AE5: =AC5/AB5 -> 0.36363636 | AF5: =V5+AC5 -> 150000
B6: 20532015 | C6: Md. Mahmudul Alam Chapol | E6: 5000 | F6: Active | G6: BTL/KYL | H6: Marketing & Sales | I6: Assistant Manager | J6: 5000 | L6: 60000 | N6: Active | O6: BTL/KYL | P6: Marketing & Sales | Q6: Assistant Manager | R6: =V6-S6 -> 60000 | S6: 10000 | U6: =S6/R6 -> 0.16666667 | V6: =L6+S6 -> 70000 | X6: Inactive | AF6: =V6+AC6 -> 70000
B7: 21072016 | C7: Md. Alamgir Mia | E7: 0 | F7: Active | G7: BTL/KYL | H7: Marketing & Sales | I7: Assistant Manager | L7: 54000 | N7: Active | O7: BTL/KYL | P7: Marketing & Sales | Q7: Assistant Manager | R7: =V7-S7 -> 54000 | S7: 4000 | U7: =S7/R7 -> 0.074074074 | V7: =L7+S7 -> 58000 | X7: Active | Y7: BTL/KYL | Z7: Marketing & Sales | AA7: Assistant Manager | AB7: =AF7-AC7 -> 58000 | AC7: 10000 | AE7: =AC7/AB7 -> 0.17241379 | AF7: =V7+AC7 -> 68000
B8: 10132009 | C8: Ahsan Shiblee | E8: 4000 | F8: Active | G8: BTL/KYL | H8: Marketing & Sales | I8: Assistant Manager | J8: 5000 | L8: 45000 | N8: Active | O8: BTL/KYL | P8: Marketing & Sales | Q8: Assistant Manager | R8: =V8-S8 -> 45000 | S8: 5000 | U8: =S8/R8 -> 0.11111111 | V8: =L8+S8 -> 50000 | X8: Active | Y8: BTL/KYL | Z8: Marketing & Sales | AA8: Assistant Manager | AB8: =AF8-AC8 -> 50000 | AC8: 10000 | AE8: =AC8/AB8 -> 0.2 | AF8: =V8+AC8 -> 60000
B9: 20092008 | C9: Khandker Mustafizur Rahman | E9: 7000 | F9: Active | G9: BTL/KYL | H9: Marketing & Sales | I9: Assistant Manager | J9: 7000 | L9: 62000 | N9: Inactive | R9: =V9-S9 -> 62000 | V9: =L9+S9 -> 62000 | X9: Inactive | AF9: =V9+AC9 -> 62000
B10: 10582007 | C10: Md. Mahabubur Rahman | E10: 2000 | F10: Active | G10: BTL/KYL | H10: Marketing & Sales | I10: Assistant Manager | J10: 3000 | L10: 35000 | N10: Active | O10: BTL/KYL | P10: Marketing & Sales | Q10: ? | R10: =V10-S10 -> 35000 | S10: 0 | U10: =S10/R10 -> 0 | V10: =L10+S10 -> 35000 | X10: Inactive | AF10: =V10+AC10 -> 35000
B11: 10782016 | C11: Mohammad Kawsar Molla | E11: 0 | F11: Active | G11: BTL/KYL | H11: Finance & Accounts | I11: Head of Finance & Accounts | J11: 0 | L11: 180000 | N11: Active | O11: BTL/KYL | P11: Finance & Accounts | Q11: Head of Finance & Accounts | R11: =V11-S11 -> 180000 | S11: 5000 | U11: =S11/R11 -> 0.027777778 | V11: =L11+S11 -> 185000 | X11: Active | Y11: BTL/KYL | Z11: Finance & Accounts | AA11: Head of Finance & Accounts | AB11: =AF11-AC11 -> 185000 | AC11: 15000 | AE11: =AC11/AB11 -> 0.081081081 | AF11: =V11+AC11 -> 200000
B12: 21152017 | C12: Mir Muhshiuzzaman | E12: 0 | F12: Active | G12: BTL/KYL | H12: Finance & Accounts | I12: Manager | J12: 5000 | L12: 105000 | N12: Active | O12: BTL/KYL | P12: Finance & Accounts | Q12: Manager | R12: =V12-S12 -> 105000 | S12: 5000 | U12: =S12/R12 -> 0.047619048 | V12: =L12+S12 -> 110000 | X12: Active | Y12: BTL/KYL | Z12: Finance & Accounts | AA12: Manager | AB12: =AF12-AC12 -> 110000 | AC12: 15000 | AE12: =AC12/AB12 -> 0.13636364 | AF12: =V12+AC12 -> 125000
B13: 20332017 | C13: Moniruzzaman | E13: 0 | F13: Active | G13: BTL/KYL | H13: Finance & Accounts | I13: Assistant Manager | J13: 7000 | L13: 67000 | N13: Active | O13: BTL/KYL | P13: Finance & Accounts | Q13: Assistant Manager | R13: =V13-S13 -> 67000 | S13: 3000 | U13: =S13/R13 -> 0.044776119 | V13: =L13+S13 -> 70000 | X13: Active | Y13: Pioneer Denim Limited | Z13: Finance & Accounts | AA13: Assistant Manager | AB13: =AF13-AC13 -> 70000 | AC13: 10000 | AE13: =AC13/AB13 -> 0.14285714 | AF13: =V13+AC13 -> 80000
B14: 20342009 | C14: Mohammad Shawkot Alam | E14: 4000 | F14: Active | G14: BTL/KYL | H14: Finance & Accounts | I14: Executive | J14: 3000 | K14: Sr. Executive | L14: 47000 | N14: Active | O14: BTL/KYL | P14: Finance & Accounts | Q14: Senior Executive | R14: =V14-S14 -> 47000 | S14: 3000 | U14: =S14/R14 -> 0.063829787 | V14: =L14+S14 -> 50000 | X14: Active | Y14: BTL/KYL | Z14: Finance & Accounts | AA14: Sr. Executive | AB14: =AF14-AC14 -> 50000 | AC14: 5000 | AE14: =AC14/AB14 -> 0.1 | AF14: =V14+AC14 -> 55000
B15: 10752016 | C15: Md. Sharforaz Hossain | E15: 0 | F15: Active | G15: BTL/KYL | H15: Finance & Accounts | I15: Officer | J15: 7000 | K15: Executive | L15: 35000 | N15: Active | O15: BTL/KYL | P15: Finance & Accounts | Q15: Executive | R15: =V15-S15 -> 35000 | S15: 5000 | U15: =S15/R15 -> 0.14285714 | V15: =L15+S15 -> 40000 | X15: Active | Y15: BTL/KYL | Z15: Finance & Accounts | AA15: Sr. Executive | AB15: =AF15-AC15 -> 40000 | AC15: 12000 | AE15: =AC15/AB15 -> 0.3 | AF15: =V15+AC15 -> 52000
B16: 10732016 | C16: Md. Bablu | E16: 0 | F16: Active | G16: BTL/KYL | H16: Finance & Accounts | I16: Officer | J16: 7000 | K16: Executive | L16: 33000 | N16: Active | O16: BTL/KYL | P16: Finance & Accounts | Q16: Executive | R16: =V16-S16 -> 33000 | S16: 5000 | U16: =S16/R16 -> 0.15151515 | V16: =L16+S16 -> 38000 | X16: Active | Y16: BTL/KYL | Z16: Finance & Accounts | AA16: Sr. Executive | AB16: =AF16-AC16 -> 38000 | AC16: 12000 | AE16: =AC16/AB16 -> 0.31578947 | AF16: =V16+AC16 -> 50000
B17: 20302005 | C17: Md. Ruhul Amin | E17: 1000 | F17: Active | G17: BTL/KYL | H17: Finance & Accounts | I17: Executive | J17: 2000 | L17: 46000 | N17: Active | O17: BTL/KYL | P17: Finance & Accounts | Q17: Executive | R17: =V17-S17 -> 46000 | S17: 4000 | U17: =S17/R17 -> 0.086956522 | V17: =L17+S17 -> 50000 | X17: Active | Y17: BTL/KYL | Z17: Finance & Accounts | AA17: Executive | AB17: =AF17-AC17 -> 50000 | AC17: 5000 | AE17: =AC17/AB17 -> 0.1 | AF17: =V17+AC17 -> 55000
B18: 10392012 | C18: Md. Abdul Motin | E18: 1000 | F18: Active | G18: BTL/KYL | H18: Finance & Accounts | I18: Jr. Officer | J18: 3000 | K18: Officer | L18: 33000 | N18: Active | O18: BTL/KYL | P18: Finance & Accounts | Q18: Officer | R18: =V18-S18 -> 33000 | S18: 5000 | U18: =S18/R18 -> 0.15151515 | V18: =L18+S18 -> 38000 | X18: Active | Y18: BTL/KYL | Z18: Finance & Accounts | AA18: Officer | AB18: =AF18-AC18 -> 38000 | AC18: 4000 | AE18: =AC18/AB18 -> 0.10526316 | AF18: =V18+AC18 -> 42000
B19: 10402012 | C19: Md. Rofiqul Islam | E19: 3000 | F19: Active | G19: BTL/KYL | H19: Finance & Accounts | I19: Jr. Executive | J19: 4000 | K19: Officer | L19: 36000 | N19: Active | O19: BTL/KYL | P19: Finance & Accounts | Q19: Officer | R19: =V19-S19 -> 36000 | S19: 5000 | U19: =S19/R19 -> 0.13888889 | V19: =L19+S19 -> 41000 | X19: Active | Y19: BTL/KYL | Z19: Finance & Accounts | AA19: Officer | AB19: =AF19-AC19 -> 41000 | AC19: 9000 | AE19: =AC19/AB19 -> 0.2195122 | AF19: =V19+AC19 -> 50000
B20: 10722016 | C20: Muhammad Masum Billah | E20: 3000 | F20: Active | G20: BTL/KYL | H20: Finance & Accounts | I20: Jr. Officer | J20: 3000 | L20: 30000 | N20: Active | O20: BTL/KYL | P20: Finance & Accounts | Q20: Jr. Officer | R20: =V20-S20 -> 30000 | S20: 3000 | U20: =S20/R20 -> 0.1 | V20: =L20+S20 -> 33000 | X20: Active | Y20: BTL/KYL | Z20: Finance & Accounts | AA20: Jr. Officer | AB20: =AF20-AC20 -> 33000 | AC20: 7000 | AE20: =AC20/AB20 -> 0.21212121 | AF20: =V20+AC20 -> 40000
B21: 10692016 | C21: Md. Oaliullah | E21: 5000 | F21: Active | G21: BTL/KYL | H21: Finance & Accounts | I21: Executive | J21: 6000 | L21: 26000 | N21: Active | O21: BTL/KYL | P21: Finance & Accounts | Q21: Executive | R21: =V21-S21 -> 26000 | S21: 6000 | U21: =S21/R21 -> 0.23076923 | V21: =L21+S21 -> 32000 | X21: Active | Y21: BTL/KYL | Z21: Finance & Accounts | AA21: Executive | AB21: =AF21-AC21 -> 32000 | AC21: 8000 | AE21: =AC21/AB21 -> 0.25 | AF21: =V21+AC21 -> 40000
B22: 20932017 | C22: Md. Humayun Kabir | E22: 0 | F22: Active | G22: BTL/KYL | H22: Finance & Accounts | I22: Executive | J22: 5000 | L22: 25000 | M22: Special 5,000 | N22: Active | O22: BTL/KYL | P22: Finance & Accounts | Q22: Executive | R22: =V22-S22 -> 25000 | S22: 5000 | U22: =S22/R22 -> 0.2 | V22: =L22+S22 -> 30000 | X22: Active | Y22: BTL/KYL | Z22: Finance & Accounts | AA22: Executive | AB22: =AF22-AC22 -> 30000 | AC22: 7000 | AE22: =AC22/AB22 -> 0.23333333 | AF22: =V22+AC22 -> 37000
B23: 20992017 | C23: Mostafizur Rahman | E23: 8000 | F23: Active | G23: BTL/KYL | H23: Finance & Accounts | I23: Trainee Officer | J23: 3000 | K23: Jr. Officer | L23: 23000 | N23: Inactive | V23: =L23+S23 -> 23000 | W23: Transferred | X23: Inactive | AB23: =AF23-AC23 -> 0
B24: 21212018 | C24: Md. Shahadat Hossain | E24: 0 | F24: Active | G24: BTL/KYL | H24: Finance & Accounts | I24: Trainee Officer | J24: 2000 | L24: 20000 | M24: Special 3,000 | N24: Active | O24: BTL/KYL | P24: Finance & Accounts | Q24: Officer | R24: =V24-S24 -> 20000 | S24: 3000 | U24: =S24/R24 -> 0.15 | V24: =L24+S24 -> 23000 | X24: Active | Y24: BTL/KYL | Z24: Finance & Accounts | AA24: Officer | AB24: =AF24-AC24 -> 23000 | AC24: 7000 | AE24: =AC24/AB24 -> 0.30434783 | AF24: =V24+AC24 -> 30000
B25: 21322018 | C25: Md. Ridoy Masud Bhuiyan | F25: Active | G25: BTL/KYL | H25: Finance & Accounts | I25: Officer | J25: 2000 | K25: - | L25: 18000 | M25: Special 3,000 | N25: Active | O25: BTL/KYL | P25: Finance & Accounts | Q25: Officer | R25: =V25-S25 -> 18000 | S25: 5000 | U25: =S25/R25 -> 0.27777778 | V25: =L25+S25 -> 23000 | X25: Active | Y25: BTL/KYL | Z25: Finance & Accounts | AA25: Officer | AB25: =AF25-AC25 -> 23000 | AC25: 7000 | AE25: =AC25/AB25 -> 0.30434783 | AF25: =V25+AC25 -> 30000
B26: 11012018 | C26: Mohammad Kabir Hossain | E26: 0 | F26: Active | G26: BTL/KYL | H26: Audit | I26: Head of Audit | J26: 0 | L26: 150000 | N26: Active | O26: BTL/KYL | P26: Audit | Q26: Head of Audit | R26: =V26-S26 -> 150000 | S26: 5000 | U26: =S26/R26 -> 0.033333333 | V26: =L26+S26 -> 155000 | X26: Active | Y26: BTL/KYL | Z26: Audit | AA26: Head of Audit | AB26: =AF26-AC26 -> 155000 | AC26: 15000 | AE26: =AC26/AB26 -> 0.096774194 | AF26: =V26+AC26 -> 170000
B27: 20282010 | C27: Md. Mehedi Hasan | E27: 0 | F27: Active | G27: BTL/KYL | H27: Audit | I27: Sr. Executive | J27: 5000 | L27: 61000 | N27: Active | O27: BTL/KYL | P27: Audit | Q27: Sr. Executive | R27: =V27-S27 -> 61000 | S27: 5000 | U27: =S27/R27 -> 0.081967213 | V27: =L27+S27 -> 66000 | X27: Active | Y27: BTL/KYL | Z27: Audit | AA27: Sr. Executive | AB27: =AF27-AC27 -> 66000 | AC27: 12000 | AE27: =AC27/AB27 -> 0.18181818 | AF27: =V27+AC27 -> 78000
B28: 21132017 | C28: Md. Moniruzzaman | E28: 0 | F28: Active | G28: BTL/KYL | H28: Audit | I28: Sr. Executive | J28: 5000 | L28: 45000 | N28: Active | O28: BTL/KYL | P28: Audit | Q28: Sr. Executive | R28: =V28-S28 -> 45000 | S28: 5000 | U28: =S28/R28 -> 0.11111111 | V28: =L28+S28 -> 50000 | X28: Active | Y28: BTL/KYL | Z28: Audit | AA28: Sr. Executive | AB28: =AF28-AC28 -> 50000 | AC28: 10000 | AE28: =AC28/AB28 -> 0.2 | AF28: =V28+AC28 -> 60000
B29: 30572016 | C29: Md. Abdus Sabur Talukder | E29: 0 | F29: Active | G29: BTL/KYL | H29: Audit | I29: Sr. Officer | J29: 4000 | L29: 30000 | N29: Active | O29: BTL/KYL | P29: Audit | Q29: Sr. Executive | R29: =V29-S29 -> 30000 | S29: 4000 | U29: =S29/R29 -> 0.13333333 | V29: =L29+S29 -> 34000 | X29: Active | Y29: BTL/KYL | Z29: Audit | AA29: Sr. Executive | AB29: =AF29-AC29 -> 34000 | AC29: 10000 | AE29: =AC29/AB29 -> 0.29411765 | AF29: =V29+AC29 -> 44000
B30: 20982017 | C30: Gobinda Chandra Dey | E30: 5000 | F30: Active | G30: BTL/KYL | H30: Audit | I30: Executive | J30: 5000 | L30: 40000 | N30: Inactive | O30: Inactive | P30: Inactive | Q30: Inactive | R30: =V30-S30 -> 0 | S30: 0 | T30: Inactive | V30: 0 | X30: Inactive | AB30: =AF30-AC30 -> 0 | AF30: =V30+AC30 -> 0
B31: 10712016 | C31: Md. Amin Ullah | E31: 7000 | F31: Active | G31: BTL/KYL | H31: Export Import Audit | I31: Executive | J31: 7000 | L31: 42000 | N31: Active | O31: BTL/KYL | P31: Export Import Audit | Q31: Asst. Manager | R31: =V31-S31 -> 42000 | S31: 5000 | U31: =S31/R31 -> 0.11904762 | V31: =L31+S31 -> 47000 | X31: Active | Y31: BTL/KYL | Z31: Export Import Audit | AA31: Assistant Manager | AB31: =AF31-AC31 -> 47000 | AC31: 23000 | AE31: =AC31/AB31 -> 0.4893617 | AF31: =V31+AC31 -> 70000
B32: 20352011 | C32: Md. Safiul Muznabin | E32: 1000 | F32: Active | G32: BTL/KYL | H32: Export Import Audit | I32: Jr. Officer | J32: 3000 | L32: 33000 | N32: Active | O32: BTL/KYL | P32: Export Import Audit | Q32: Sr. Executive | R32: =V32-S32 -> 33000 | S32: 3000 | U32: =S32/R32 -> 0.090909091 | V32: =L32+S32 -> 36000 | X32: Active | Y32: BTL/KYL | Z32: Export Import Audit | AA32: Sr. Executive | AB32: =AF32-AC32 -> 36000 | AC32: 4000 | AE32: =AC32/AB32 -> 0.11111111 | AF32: =V32+AC32 -> 40000
B33: 21232018 | C33: Md. Shafiqul Islam | E33: 0 | F33: Active | G33: BTL/KYL | H33: Export Import Audit | I33: Trainee Officer | J33: 3000 | L33: 20000 | N33: Active | O33: BTL/KYL | P33: Export Import Audit | Q33: Executive | R33: =V33-S33 -> 20000 | S33: 5000 | U33: =S33/R33 -> 0.25 | V33: =L33+S33 -> 25000 | X33: Active | Y33: BTL/KYL | Z33: Export Import Audit | AA33: Executive | AB33: =AF33-AC33 -> 25000 | AC33: 5000 | AE33: =AC33/AB33 -> 0.2 | AF33: =V33+AC33 -> 30000
B34: 20842017 | C34: Yousuf Ahmmed | E34: 4000 | F34: Active | G34: BTL/KYL | H34: Export Import Audit | I34: Officer | J34: 7000 | L34: 25000 | N34: Active | O34: BTL/KYL | P34: Export Import Audit | Q34: Sr. Executive | R34: =V34-S34 -> 25000 | S34: 5000 | U34: =S34/R34 -> 0.2 | V34: =L34+S34 -> 30000 | X34: Active | Y34: BTL/KYL | Z34: Export Import Audit | AA34: Sr. Executive | AB34: =AF34-AC34 -> 30000 | AC34: 7000 | AE34: =AC34/AB34 -> 0.23333333 | AF34: =V34+AC34 -> 37000
B35: 11092018 | C35: Mosharraf Hossain Chowdhury (Faisal) | E35: 0 | F35: Inactive | G35: Inactive | H35: Inactive | I35: Inactive | J35: 0 | K35: Inactive | L35: 0 | M35: Inactive | N35: Active | O35: BTL/KYL | P35: Import | Q35: Deputy General Manager | R35: =V35-S35 -> 100000 | S35: 10000 | U35: =S35/R35 -> 0.1 | V35: 110000 | X35: Active | Y35: BTL/KYL | Z35: Import | AA35: Deputy General Manager | AB35: =AF35-AC35 -> 110000 | AC35: 30000 | AE35: =AC35/AB35 -> 0.27272727 | AF35: =V35+AC35 -> 140000
B36: 30211994 | C36: Ashadullaha Ahamed | E36: 2000 | F36: Active | G36: BTL/KYL | H36: Import | I36: Incharge | J36: 3000 | L36: 65000 | N36: Active | O36: BTL/KYL | P36: Import | Q36: Incharge | R36: =V36-S36 -> 65000 | S36: 5000 | U36: =S36/R36 -> 0.076923077 | V36: =L36+S36 -> 70000 | X36: Active | Y36: BTL/KYL | Z36: Import | AA36: Incharge | AB36: =AF36-AC36 -> 70000 | AC36: 20000 | AE36: =AC36/AB36 -> 0.28571429 | AF36: =V36+AC36 -> 90000
B37: 10252008 | C37: Azmul Karim | E37: 1000 | F37: Active | G37: BTL/KYL | H37: Import | I37: Executive | J37: 3000 | L37: 40000 | N37: Active | O37: Pioneer Denim Limited | P37: Import | Q37: Assistant Manager | R37: =V37-S37 -> 40000 | S37: 6000 | U37: =S37/R37 -> 0.15 | V37: =L37+S37 -> 46000 | X37: Active | Y37: Pioneer Denim Limited | Z37: Import | AA37: Assistant Manager | AB37: =AF37-AC37 -> 46000 | AC37: 14000 | AE37: =AC37/AB37 -> 0.30434783 | AF37: =V37+AC37 -> 60000
B38: 21032017 | C38: Md. Moshiur Rahman | E38: 0 | F38: Active | G38: BTL/KYL | H38: Import | I38: Trainee Officer | J38: 5000 | L38: 20000 | N38: Active | O38: BTL/KYL | P38: Import | Q38: Trainee Officer | R38: =V38-S38 -> 20000 | S38: 6000 | U38: =S38/R38 -> 0.3 | V38: =L38+S38 -> 26000 | X38: Active | Y38: BTL/KYL | Z38: Import | AA38: Trainee Officer | AB38: =AF38-AC38 -> 26000 | AC38: 9000 | AE38: =AC38/AB38 -> 0.34615385 | AF38: =V38+AC38 -> 35000
B39: 30150000 | C39: Md. Rabiul Alam | E39: 1000 | F39: Active | G39: BTL/KYL | H39: Procurement | I39: Head of Procurement | J39: 3000 | L39: 84000 | N39: Active | O39: BTL/KYL | P39: Procurement | Q39: Head of Procurement | R39: =V39-S39 -> 84000 | S39: 6000 | U39: =S39/R39 -> 0.071428571 | V39: =L39+S39 -> 90000 | X39: Active | Y39: BTL/KYL | Z39: Procurement | AA39: Head of Procurement | AB39: =AF39-AC39 -> 90000 | AC39: 10000 | AE39: =AC39/AB39 -> 0.11111111 | AF39: =V39+AC39 -> 100000
B40: 10882017 | C40: Md. Farid Uddin | E40: 0 | F40: Active | G40: BTL/KYL | H40: Procurement | I40: ? | J40: 3000 | L40: 18000 | N40: Inactive | R40: =V40-S40 -> 0 | V40: 0 | X40: Inactive | AB40: =AF40-AC40 -> 0
...

Sheet Sheet4
A1: Business_Unit_20 | B1: Pioneer Denim Limited
A2: Department_20 | B2: Administration
A4: Row Labels | B4: Sum of Increment_20 | C4: Sum of Perc_20 | D4: Sum of Salary_20
A5: Bayazid Hossen Gulzar | B5: 5000 | C5: 0.37154989 | D5: 17000
A6: Messenger | B6: 5000 | C6: 0.37154989 | D6: 17000
A7: Jalal Gazi | B7: 2000 | C7: 0.11889597 | D7: 17000
A8: Cleaner | B8: 2000 | C8: 0.11889597 | D8: 17000
A9: Jashim Uddin | B9: 2000 | C9: 0.12738854 | D9: 16000
A10: Messenger | B10: 2000 | C10: 0.12738854 | D10: 16000
A11: Md. Habib Prodhan | B11: 0 | C11: 0 | D11: 12000
A12: Messenger | B12: 0 | C12: 0 | D12: 12000
A13: Md. Mehedi Hasan | B13: 2000 | C13: 0.12738854 | D13: 16000
A14: Messenger | B14: 2000 | C14: 0.12738854 | D14: 16000
A15: Md. Saiful Islam | B15: 2000 | C15: 0.12738854 | D15: 16000
A16: Messenger | B16: 2000 | C16: 0.12738854 | D16: 16000
... A19: Grand Total | B19: 15000 | C19: 1 | D19: 110000

Sheet Sheet5
A1: Name | B1: Abrar Rahman Siam
A3: Sum of Increment_17 | B3: Sum of Increment_18 | C3: Sum of Increment_20
A4: 0 | B4: 7000 | C4: 5000
E6: =GETPIVOTDATA("Sum of Increment_17",$A$3) -> 0 | F6: =GETPIVOTDATA("Sum of Increment_18",$A$3) -> 7000 | G6: =GETPIVOTDATA("Sum of Increment_20",$A$3) -> 5000

Sheet 2019
A1: SL | B1: ID | C1: Name | D1: DOJ | E1: Emp_Status | F1: Business_Unit_18 | G1: Department_18 | H1: Position_18 | I1: Previous Salary_18 | J1: Increment_18 | K1: Promotion_18 | L1: Perc_18 | M1: Salary_18 | N1: Remarks_18
B2: 10062011 | C2: Md. Kamruzzaman | E2: Active | F2: BTL/KYL | G2: Marketing & Sales | H2: Head of Marketing & Sales | I2: 102000 | J2: 48000 | L2: 0.47058824 | M2: 150000 | N2: AE: 25k, SP: 23k
B3: 20042012 | C3: Mohammed Nurul Akter Chowdhury | E3: Active | F3: BTL/KYL | G3: Marketing & Sales | H3: Head of Marketing (Rotor) | I3: 100000 | J3: 20000 | L3: 0.2 | M3: 120000
B4: 10042008 | C4: Liton Apu Biswas | E4: Active | F4: BTL/KYL | G4: Marketing & Sales | H4: Head of Marketing (North Zone) | I4: 100000 | J4: 20000 | L4: 0.2 | M4: 120000
B5: 10052012 | C5: Md. Abdul Maleque | E5: Active | F5: BTL/KYL | G5: Marketing & Sales | H5: Head of Marketing (Middle Zone) | I5: 90000 | J5: 20000 | L5: 0.22222222 | M5: 110000
B6: 20532015 | C6: Md. Mahmudul Alam Chapol | E6: Active | F6: BTL/KYL | G6: Marketing & Sales | H6: Assistant Manager | I6: 60000 | J6: 10000 | L6: 0.16666667 | M6: 70000
B7: 21072016 | C7: Md. Alamgir Mia | E7: Active | F7: BTL/KYL | G7: Marketing & Sales | H7: Assistant Manager | I7: 54000 | J7: 4000 | L7: 0.074074074 | M7: 58000
B8: 10132009 | C8: Ahsan Shiblee | E8: Active | F8: BTL/KYL | G8: Marketing & Sales | H8: Assistant Manager | I8: 45000 | J8: 5000 | L8: 0.11111111 | M8: 50000
B9: 10582007 | C9: Md. Mahabubur Rahman | E9: Active | F9: BTL/KYL | G9: Marketing & Sales | H9: ? | I9: 35000 | J9: 0 | L9: 0 | M9: 35000
B10: 10782016 | C10: Mohammad Kawsar Molla | E10: Active | F10: BTL/KYL | G10: Finance & Accounts | H10: Head of Finance & Accounts | I10: 180000 | J10: 5000 | L10: 0.027777778 | M10: 185000
B11: 21152017 | C11: Mir Muhshiuzzaman | E11: Active | F11: BTL/KYL | G11: Finance & Accounts | H11: Manager | I11: 105000 | J11: 5000 | L11: 0.047619048 | M11: 110000
B12: 20332017 | C12: Moniruzzaman | E12: Active | F12: BTL/KYL | G12: Finance & Accounts | H12: Assistant Manager | I12: 67000 | J12: 3000 | L12: 0.044776119 | M12: 70000
B13: 20342009 | C13: Mohammad Shawkot Alam | E13: Active | F13: BTL/KYL | G13: Finance & Accounts | H13: Senior Executive | I13: 47000 | J13: 3000 | L13: 0.063829787 | M13: 50000
B14: 10752016 | C14: Md. Sharforaz Hossain | E14: Active | F14: BTL/KYL | G14: Finance & Accounts | H14: Executive | I14: 35000 | J14: 5000 | L14: 0.14285714 | M14: 40000
... B43: 20072000 | C43: Rakibul Hasan Chowdhury | E43: Active | F43: BTL/KYL | G43: Commercial | H43: Incharge | I43: 55000 | J43: 4000 | L43: 0.072727273 | M43: 59000
B44: 20122009 | C44: Syed Mahmood Hassan | E44: Active | F44: BTL/KYL | G44: Commercial | H44: Jr. Officer | I44: 35000 | J44: 6000 | L44: 0.17142857 | M44: 41000 | N44: AI: 3k, SP: 3k
B45: 21142017 | C45: Sohebul Islam | E45: Active | F45: BTL/KYL | G45: Commercial | H45: Jr. Officer | I45: 22000 | J45: 5000 | L45: 0.22727273 | M45: 27000
B46: 10542014 | C46: Md. Foysal Hassan | E46: Active | F46: BTL/KYL | G46: Commercial | H46: Executive | I46: 25000 | J46: 4000 | L46: 0.16 | M46: 29000
B47: 10192011 | C47: Md. Kamal Ahmed | E47: Active | F47: BTL/KYL | G47: Commercial | H47: Jr. Officer | I47: 27000 | J47: 5000 | L47: 0.18518519 | M47: 32000
B48: 20062000 | C48: Asraful Islam | E48: Active | F48: BTL/KYL | G48: Commercial | H48: Incharge | I48: 63000 | J48: 5000 | L48: 0.079365079 | M48: 68000
B49: 10112004 | C49: Mohmmad Omar Faruque | E49: Active | F49: BTL/KYL | G49: Commercial | H49: Executive | I49: 35000 | J49: 5000 | L49: 0.14285714 | M49: 40000
B50: 20172012 | C50: Md. Al-Amin Khan | E50: Active | F50: BTL/KYL | G50: Legal & Estate | H50: Executive | I50: 26000 | J50: 4000 | L50: 0.15384615 | M50: 30000
B51: 21312018 | C51: Muhammad Milon Hossain Molla | E51: Active | F51: BTL/KYL | G51: Commercial | H51: ? | I51: 14000 | J51: 6000 | L51: 0.42857143 | M51: 20000
B52: 10202011 | C52: Muhammad Momin Hossen | E52: Active | F52: BTL/KYL | G52: Commercial | H52: Executive | I52: 22000 | J52: 3000 | L52: 0.13636364 | M52: 25000
B53: 10212011 | C53: Md. Shakamal | E53: Active | F53: BTL/KYL | G53: Commercial | H53: ? | I53: 22000 | J53: 5000 | L53: 0.22727273 | M53: 27000
B54: 10222012 | C54: Ashiqur Rahman Robin | E54: Active | F54: BTL/KYL | G54: Commerical | H54: ? | I54: 22000 | J54: 8000 | L54: 0.36363636 | M54: 30000
B55: 10522014 | C55: Arshadul Haque Molla | E55: Active | F55: BTL/KYL | G55: Commercial | H55: ? | I55: 20000 | J55: 3000 | L55: 0.15 | M55: 23000
B56: 20892017 | C56: Mahamudun Nabi Ove | E56: Active | F56: BTL/KYL | G56: Commercial | H56: Jr. Executive | I56: 15000 | J56: 5000 | L56: 0.33333333 | M56: 20000
... B97: 21422018 | C97: Md. Karimul | E97: Active | F97: BTL/KYL | G97: Administration | H97: Lift Man | I97: 14000 | J97: 2000 | L97: 0.14285714 | M97: 16000
B98: 21392018 | C98: Md. Mehedi Hasan | E98: Active | F98: BTL/KYL | G98: Administration | H98: Peon | I98: 10000 | J98: 4000 | L98: 0.4 | M98: 14000 | N98: As per Grading
B99: 21382018 | C99: Md. Jamal Hossain | E99: Active | F99: BTL/KYL | G99: Administration | H99: Peon | I99: 10000 | J99: 2000 | L99: 0.2 | M99: 12000
B100: 21512019 | C100: Nasima | E100: Active | F100: BTL/KYL | G100: Administration | H100: Asst. Cook | I100: 9000 | J100: 1000 | L100: 0.11111111 | M100: 10000
B101: 21412018 | C101: Md. Masud Rana | E101: Active | F101: BTL/KYL | G101: Administration | H101: Asst. Cook | I101: 10000 | J101: 3000 | L101: 0.3 | M101: 13000
B102: 21252018 | C102: Md. Shazib Madbar | E102: Active | F102: BTL/KYL | G102: Transport | H102: Driver | I102: 18000 | J102: 1000 | L102: 0.055555556 | M102: 19000 | N102: Grade A
B103: 20522011 | C103: Md. Lokman Hossain | E103: Active | F103: BTL/KYL | G103: Transport | H103: Driver | I103: 17000 | J103: 2000 | L103: 0.11764706 | M103: 19000 | N103: Grade A
B104: 21242018 | C104: Md. Rubel | E104: Active | F104: BTL/KYL | G104: Transport | H104: Driver | I104: 17000 | J104: 2000 | L104: 0.11764706 | M104: 19000 | N104: Grade A
B105: 10612015 | C105: Md. Abu Hanif | E105: Active | F105: BTL/KYL | G105: Transport | H105: Driver | I105: 17000 | J105: 2000 | L105: 0.11764706 | M105: 19000 | N105: Grade A
B106: 11152018 | C106: Md. Asaduzzaman Fakir | E106: Active | F106: BTL/KYL | G106: Transport | H106: Driver | I106: 17000 | J106: 1000 | L106: 0.058823529 | M106: 18000 | N106: Grade B
B107: 11282018 | C107: Md. Shahjada Bhuiyan | E107: Active | F107: BTL/KYL | G107: Audit | H107: Assistant Manager | I107: 42000 | J107: 0 | L107: 0 | M107: 42000
B108: 21452019 | C108: Md. Masum Billah | E108: Active | F108: BTL/KYL | G108: Audit | H108: Audit Assistant | I108: 14000 | J108: 2000 | L108: 0.14285714 | M108: 16000
...

Sheet 2020
A1: SL | B1: ID | C1: Name | D1: DOJ | E1: Employment | F1: Business_Unit_20 | G1: Department_20 | H1: Position_20 | I1: Previous Salary | J1: Increment_20 | K1: Promotion_20 | L1: Perc_20 | M1: Salary_20 | N1: Remarks_20
B3: 20862017 | C3: Md. Shamim Hossain | E3: Active | F3: BTL/KYL | G3: Administration | H3: ? | I3: 24000 | J3: 6000 | L3: 0.25 | M3: 30000
B4: 21062016 | C4: Md. Shahin Alom | E4: Active | F4: BTL/KYL | G4: Administration | H4: Receptionist | I4: 22000 | J4: 7000 | L4: 0.31818182 | M4: 29000
B5: 10431999 | C5: Md. Azam Pasha | E5: Active | F5: BTL/KYL | G5: Administration | H5: Peon | I5: 18000 | J5: 2000 | L5: 0.11111111 | M5: 20000
B6: 10632016 | C6: Abul Bashar Sheikh | E6: Active | F6: BTL/KYL | G6: Administration | H6: Cleaner | I6: 15000 | J6: 2000 | L6: 0.13333333 | M6: 17000
B7: 20420000 | C7: Md. Anis Miah | E7: Active | F7: BTL/KYL | G7: Administration | H7: Peon | I7: 16000 | J7: 2000 | L7: 0.125 | M7: 18000
B8: 21082017 | C8: Md. Alamgir Hossain | E8: Active | F8: BTL/KYL | G8: Administration | H8: Peon | I8: 13000 | J8: 3000 | L8: 0.23076923 | M8: 16000
B9: 20872017 | C9: Mamun Hossen | E9: Active | F9: BTL/KYL | G9: Administration | H9: Peon | I9: 13000 | J9: 3000 | L9: 0.23076923 | M9: 16000
B10: 20412000 | C10: Md. Tamiz Uddin | E10: Active | F10: BTL/KYL | G10: Administration | H10: Cook | I10: 16000 | J10: 2000 | L10: 0.125 | M10: 18000
B11: 20442006 | C11: Md. Kabir | E11: Active | F11: BTL/KYL | G11: Administration | H11: Cook | I11: 16000 | J11: 2000 | L11: 0.125 | M11: 18000
B12: 21012017 | C12: Md. Foysal Hossen | E12: Active | F12: BTL/KYL | G12: Administration | H12: Asst. Cook | I12: 12000 | J12: 2000 | L12: 0.16666667 | M12: 14000
B13: 21022017 | C13: Md. Sohel Hossen | E13: Active | F13: BTL/KYL | G13: Administration | H13: Peon | I13: 12000 | J13: 2000 | L13: 0.16666667 | M13: 14000
B14: 11082018 | C14: Md. Miraz Molla | E14: Active | F14: BTL/KYL | G14: Administration | H14: Receiptionist | I14: 15000 | J14: 5000 | L14: 0.33333333 | M14: 20000
... B17: 21442018 | C17: Dinaj Mia | E17: Active | F17: BTL/KYL | G17: Administration | H17: Peon | I17: 10000 | J17: 2000 | L17: 0.2 | M17: 12000
B18: 11352020 | C18: Abdullah Al Arif | E18: Active | F18: BTL/KYL | G18: Administration | H18: Manager | I18: 50000 | J18: 8000 | L18: 0.16 | M18: 50000 | N18: Sp: 8k
B19: 21712019 | C19: Md. Shahjahan Mia | E19: Active | F19: BTL/KYL | G19: Administration | H19: Security | I19: 30000 | J19: 2000 | L19: 0.066666667 | M19: 32000
B20: 11482020 | C20: Dewan Md. Liaqat Ali | E20: Active | F20: BTL/KYL | G20: Administration | H20: Head of Administration | I20: 150000 | J20: 0 | L20: 0 | M20: 150000
B21: 21852020 | C21: S. M. Arif Ahmed | E21: Active | F21: BTL/KYL | G21: Administration | H21: Manager | I21: 50000 | J21: 0 | L21: 0 | M21: 50000
B22: 21662019 | C22: Md. Sakawat Hossain Apon | E22: Active | F22: BTL/KYL | G22: Administration | H22: Peon | I22: 11000 | J22: 2000 | L22: 0.18181818 | M22: 13000
B23: 21702019 | C23: Md. Riad Hossain | E23: Active | F23: BTL/KYL | G23: Administration | H23: Peon | I23: 10000 | J23: 2000 | L23: 0.2 | M23: 12000
B24: 21492019 | C24: Imam Hossain | E24: Active | F24: BTL/KYL | G24: Administration | H24: Asst. Cook | I24: 10000 | J24: 2000 | L24: 0.2 | M24: 12000
B25: 21592019 | C25: Md. Sohag Hossain | E25: Active | F25: BTL/KYL | G25: Administration | H25: Asst. Cook | I25: 8000 | J25: 3000 | L25: 0.375 | M25: 11000
B26: 21652019 | C26: Md. Mostafa Kamal | E26: Active | F26: BTL/KYL | G26: Administration | H26: Asst. Cook | I26: 9000 | J26: 2000 | L26: 0.22222222 | M26: 11000
B27: 21672019 | C27: Md. Salim Miha | E27: Active | F27: BTL/KYL | G27: Administration | H27: Asst. Cook | I27: 9000 | J27: 2000 | L27: 0.22222222 | M27: 11000
B28: 11012018 | C28: Mohammad Kabir Hossain | E28: Active | F28: BTL/KYL | G28: Audit | H28: Head of Audit | I28: 155000 | J28: 15000 | L28: 0.096774194 | M28: 170000
B29: 20282010 | C29: Md. Mehedi Hasan | E29: Active | F29: BTL/KYL | G29: Audit | H29: Sr. Executive | I29: 66000 | J29: 12000 | L29: 0.18181818 | M29: 78000
B30: 21132017 | C30: Md. Moniruzzaman | E30: Active | F30: BTL/KYL | G30: Audit | H30: Sr. Executive | I30: 50000 | J30: 10000 | L30: 0.2 | M30: 60000
... B32: 21452019 | C32: Md. Masum Billah | E32: Active | F32: BTL/KYL | G32: Audit | H32: Audit Assistant | I32: 16000 | J32: 5000 | L32: 0.3125 | M32: 21000
B33: 11432020 | C33: Md. Azam Ali | E33: Active | F33: BTL/KYL | G33: Audit | H33: Executive | I33: 35000 | J33: 0 | M33: 35000
B34: 20072000 | C34: Rakibul Hasan Chowdhury | E34: Active | F34: BTL/KYL | G34: Commercial | H34: Incharge | I34: 59000 | J34: 8000 | L34: 0.13559322 | M34: 67000
B35: 20122009 | C35: Syed Mahmood Hassan | E35: Active | F35: BTL/KYL | G35: Commercial | H35: Jr. Officer | I35: 41000 | J35: 5000 | L35: 0.12195122 | M35: 46000
B36: 21142017 | C36: Sohebul Islam | E36: Active | F36: BTL/KYL | G36: Commercial | H36: Jr. Officer | I36: 27000 | J36: 8000 | L36: 0.2962963 | M36: 35000
B37: 10542014 | C37: Md. Foysal Hassan | E37: Active | F37: BTL/KYL | G37: Commercial | H37: Executive | I37: 29000 | J37: 6000 | L37: 0.20689655 | M37: 35000
B38: 10192011 | C38: Md. Kamal Ahmed | E38: Active | F38: BTL/KYL | G38: Commercial | H38: Jr. Officer | I38: 32000 | J38: 6000 | L38: 0.1875 | M38: 38000
B39: 20062000 | C39: Asraful Islam | E39: Active | F39: BTL/KYL | G39: Commercial | H39: Incharge | I39: 68000 | J39: 12000 | L39: 0.17647059 | M39: 80000
B40: 21312018 | C40: Muhammad Milon Hossain Molla | E40: Active | F40: BTL/KYL | G40: Commercial | H40: Trainee Officer | I40: 20000 | J40: 6000 | L40: 0.3 | M40: 26000
B41: 10212011 | C41: Md. Shakamal | E41: Active | F41: BTL/KYL | G41: Commercial | H41: ? | I41: 27000 | J41: 5000 | L41: 0.18518519 | M41: 32000
B42: 10222012 | C42: Ashiqur Rahman Robin | E42: Active | F42: BTL/KYL | G42: Commercial | H42: ? | I42: 30000 | J42: 5000 | L42: 0.16666667 | M42: 35000
B43: 10522014 | C43: Arshadul Haque Molla | E43: Active | F43: BTL/KYL | G43: Commercial | H43: ? | I43: 23000 | J43: 5000 | L43: 0.2173913 | M43: 28000
B44: 20892017 | C44: Mahamudun Nabi Ove | E44: Active | F44: BTL/KYL | G44: Commercial | H44: Jr. Executive | I44: 20000 | J44: 5000 | L44: 0.25 | M44: 25000
...

Sheet TS_PDL
B3: SL | C3: Department Name | D3: 2020 | I3: 2019-2018
D4: Increment Amount | E4: No's of Employee Appraised | F4: Average Increment Per Person | G4: Increasing % | H4: increasing % in Total | I4: Increment Amount | J4: No's of Employee Appraised | K4: Average Increment Per Person | L4: Increasing % | M4: increasing % in Total | S4: Department | T4: 2019 | U4: 2020
B5: 1 | C5: Marketing | D5: ='2020_PDL'!Q32 -> 116000 | E5: ='2020_PDL'!R32 -> 19 | F5: =D5/E5 -> 6105.2632 | G5: ='2020_PDL'!S32 -> 0.19840872 | H5: ='2020_PDL'!U32 -> 0.071604938 | I5: ='2019_PDL'!Q122 -> 40000 | J5: ='2019_PDL'!R122 -> 7 | K5: =I5/J5 -> 5714.2857 | L5: ='2019_PDL'!S122 -> 0.20122655 | M5: ='2019_PDL'!U122 -> 0.026092629 | S5: Marketing | T5: 40000 | U5: 116000
B6: 2 | C6: Finance & Accounts | D6: ='2020_PDL'!Q33 -> 62000 | E6: ='2020_PDL'!R33 -> 9 | F6: =D6/E6 -> 6888.8889 | G6: ='2020_PDL'!S33 -> 0.22847122 | H6: ='2020_PDL'!U33 -> 0.14351852 | I6: ='2019_PDL'!Q123 -> 41000 | J6: ='2019_PDL'!R123 -> 6 | K6: =I6/J6 -> 6833.3333 | L6: ='2019_PDL'!S123 -> 0.26227106 | M6: ='2019_PDL'!U123 -> 0.094907407 | S6: Finance & Accounts | T6: 41000 | U6: 62000
B7: 3 | C7: Audit | D7: ='2020_PDL'!Q34 -> 8000 | E7: ='2020_PDL'!R34 -> 4 | F7: =D7/E7 -> 2000 | G7: ='2020_PDL'!S34 -> 0.044444444 | H7: ='2020_PDL'!U34 -> 0.037383178 | I7: ='2019_PDL'!Q124 -> 8000 | J7: ='2019_PDL'!R124 -> 2 | K7: =I7/J7 -> 4000 | L7: ='2019_PDL'!S124 -> 0.10535714 | M7: ='2019_PDL'!U124 -> 0.028776978 | S7: Audit | T7: 8000 | U7: 8000
B8: 4 | C8: Procurement | D8: ='2020_PDL'!Q35 -> 43000 | E8: ='2020_PDL'!R35 -> 7 | F8: =D8/E8 -> 6142.8571 | G8: ='2020_PDL'!S35 -> 0.18954816 | H8: ='2020_PDL'!U35 -> 0.19111111 | I8: ='2019_PDL'!Q125 -> 29000 | J8: ='2019_PDL'!R125 -> 6 | K8: =I8/J8 -> 4833.3333 | L8: ='2019_PDL'!S125 -> 0.17766695 | M8: ='2019_PDL'!U125 -> 0.14146341 | S8: Procurement | T8: 29000 | U8: 43000
B9: 5 | C9: Commercial | D9: ='2020_PDL'!Q36 -> 86000 | E9: ='2020_PDL'!R36 -> 14 | F9: =D9/E9 -> 6142.8571 | G9: ='2020_PDL'!S36 -> 0.30007728 | H9: ='2020_PDL'!U36 -> 0.22279793 | I9: ='2019_PDL'!Q126 -> 40000 | J9: ='2019_PDL'!R126 -> 10 | K9: =I9/J9 -> 4000 | L9: ='2019_PDL'!S126 -> 0.21089032 | M9: ='2019_PDL'!U126 -> 0.13513514 | S9: Commercial | T9: 40000 | U9: 86000
B10: 6 | C10: Import | D10: ='2020_PDL'!Q37 -> 26000 | E10: ='2020_PDL'!R37 -> 3 | F10: =D10/E10 -> 8666.6667 | G10: ='2020_PDL'!S37 -> 0.29589372 | H10: ='2020_PDL'!U37 -> 0.29213483 | I10: ='2019_PDL'!Q127 -> 14000 | J10: ='2019_PDL'!R127 -> 3 | K10: =I10/J10 -> 4666.6667 | L10: ='2019_PDL'!S127 -> 0.17222222 | M10: ='2019_PDL'!U127 -> 0.14285714 | S10: Import | T10: 14000 | U10: 26000
B11: 7 | C11: Customs | D11: ='2020_PDL'!Q38 -> 15000 | E11: ='2020_PDL'!R38 -> 2 | F11: =D11/E11 -> 7500 | G11: ='2020_PDL'!S38 -> 0.16666667 | H11: ='2020_PDL'!U38 -> 0.16666667 | I11: ='2019_PDL'!Q128 -> 0 | J11: ='2019_PDL'!R128 -> 0 | K11: 0 | L11: ='2019_PDL'!S128 -> 0 | M11: ='2019_PDL'!U128 -> 0 | S11: Customs | T11: 0 | U11: 15000
B12: 8 | C12: Planning & Coordination | D12: ='2020_PDL'!Q39 -> 17000 | E12: ='2020_PDL'!R39 -> 3 | F12: =D12/E12 -> 5666.6667 | G12: ='2020_PDL'!S39 -> 0.098941005 | H12: ='2020_PDL'!U39 -> 0.089473684 | I12: ='2019_PDL'!Q129 -> 0 | J12: ='2019_PDL'!R129 -> 0 | K12: 0 | L12: ='2019_PDL'!S129 -> 0 | M12: ='2019_PDL'!U129 -> 0 | S12: Planning & Coordination | T12: 0 | U12: 17000
B13: 9 | C13: Costing | D13: ='2020_PDL'!Q40 -> 3000 | E13: ='2020_PDL'!R40 -> 1 | F13: =D13/E13 -> 3000 | G13: ='2020_PDL'!S40 -> 0.02 | H13: ='2020_PDL'!U40 -> 0.015625 | I13: ='2019_PDL'!Q130 -> 0 | J13: ='2019_PDL'!R130 -> 1 | K13: =I13/J13 -> 0 | L13: ='2019_PDL'!S130 -> 0 | M13: ='2019_PDL'!U130 -> 0 | S13: Costing | T13: 0 | U13: 3000
B14: 10 | C14: Information Technology | D14: ='2020_PDL'!Q41 -> 0 | E14: ='2020_PDL'!R41 -> 3 | F14: =D14/E14 -> 0 | G14: ='2020_PDL'!S41 -> 0 | H14: ='2020_PDL'!U41 -> 0 | I14: ='2019_PDL'!Q131 -> 0 | J14: ='2019_PDL'!R131 -> 0 | K14: 0 | L14: ='2019_PDL'!S131 -> 0 | M14: ='2019_PDL'!U131 -> 0 | S14: Information Technology | T14: 0 | U14: 0
B15: 11 | C15: Administration | D15: ='2020_PDL'!Q42 -> 15000 | E15: ='2020_PDL'!R42 -> 7 | F15: =D15/E15 -> 2142.8571 | G15: ='2020_PDL'!S42 -> 0.16020408 | H15: ='2020_PDL'!U42 -> 0.21126761 | I15: ='2019_PDL'!Q132 -> 18000 | J15: ='2019_PDL'!R132 -> 6 | K15: =I15/J15 -> 3000 | L15: ='2019_PDL'!S132 -> 0.24522398 | M15: ='2019_PDL'!U132 -> 0.18556701 | S15: Administration | T15: 18000 | U15: 15000
D16: =SUM(D5:D15) -> 391000 | E16: =SUM(E5:E15) -> 72 | F16: =D16/E16 -> 5430.5556 | G16: =AVERAGE(G5:G15) -> 0.15478685 | H16: ='2020'!Q179 -> 0.10671397 | I16: =SUM(I5:I15) -> 190000 | J16: =SUM(J5:J15) -> 41 | K16: =I16/J16 -> 4634.1463 | L16: =AVERAGE(L5:L15) -> 0.12498711 | M16: ='2019_PDL'!Q136 -> 0.057944495

Sheet 2020_PDL
A1: SL | B1: ID | C1: Name | D1: DOJ | E1: Employment | F1: Business_Unit_20 | G1: Department_20 | H1: Position_20 | I1: Previous Salary | J1: Increment_20 | K1: Promotion_20 | L1: Perc_20 | M1: Salary_20 | N1: Remarks_20
A2: 1 | B2: 10582015 | C2: Jashim Uddin | E2: Active | F2: Pioneer Denim Limited | G2: Administration | H2: Messenger | I2: 14000 | J2: 2000 | L2: 0.14285714 | M2: 16000
A3: 2 | B3: 20792016 | C3: Md. Saiful Islam | E3: Active | F3: Pioneer Denim Limited | G3: Administration | H3: Messenger | I3: 14000 | J3: 2000 | L3: 0.14285714 | M3: 16000
A4: 3 | B4: 21122017 | C4: Robin | E4: Active | F4: Pioneer Denim Limited | G4: Administration | H4: Messenger | I4: 14000 | J4: 2000 | L4: 0.14285714 | M4: 16000
A5: 4 | B5: 21392018 | C5: Md. Mehedi Hasan | E5: Active | F5: Pioneer Denim Limited | G5: Administration | H5: Messenger | I5: 14000 | J5: 2000 | L5: 0.14285714 | M5: 16000
A6: 5 | B6: 40332018 | C6: Jalal Gazi | E6: Active | F6: Pioneer Denim Limited | G6: Administration | H6: Cleaner | I6: 15000 | J6: 2000 | L6: 0.13333333 | M6: 17000
A7: 6 | B7: 40962020 | C7: Md. Habib Prodhan | E7: Active | F7: Pioneer Denim Limited | G7: Administration | H7: Messenger | I7: 12000 | J7: 0 | L7: 0 | M7: 12000
A8: 7 | B8: 40972020 | C8: Bayazid Hossen Gulzar | E8: Active | F8: Pioneer Denim Limited | G8: Administration | H8: Messenger | I8: 12000 | J8: 5000 | L8: 0.41666667 | M8: 17000
A9: 8 | B9: 20812016 | C9: Md. Yeakub Ali | E9: Active | F9: Pioneer Denim Limited | G9: Audit | H9: Officer | I9: 45000 | J9: 8000 | L9: 0.17777778 | M9: 53000
A10: 9 | B10: 41122020 | C10: Mahbubur Rahman Chowdhury | E10: Active | F10: Pioneer Denim Limited | G10: Audit | H10: Executive | I10: 28000 | J10: 0 | L10: 0 | M10: 28000
A11: 10 | B11: 41132020 | C11: Md. Ariful Islam | E11: Active | F11: Pioneer Denim Limited | G11: Audit | H11: Executive | I11: 28000 | J11: 0 | L11: 0 | M11: 28000
A12: 11 | B12: 41162020 | C12: Omar Khaium | E12: Active | F12: Pioneer Denim Limited | G12: Audit | H12: Manager | I12: 63000 | J12: 0 | L12: 0 | M12: 63000
A13: 12 | B13: 10092005 | C13: Md. Saifur Rahaman | E13: Active | F13: Pioneer Denim Limited | G13: Commercial | H13: Sr. Executive | I13: 52000 | J13: 8000 | L13: 0.15384615 | M13: 60000
... A29: 28 | B29: 30702018 | C29: Md. Humayun Kobir | E29: Active | F29: Pioneer Denim Limited | G29: Customs | H29: Executive | I29: 30000 | J29: 5000 | L29: 0.16666667 | M29: 35000
A30: 29 | B30: 20332017 | C30: Moniruzzaman | E30: Active | F30: Pioneer Denim Limited | G30: Finance & Accounts | H30: Assistant Manager | I30: 70000 | J30: 10000 | L30: 0.14285714 | M30: 80000 | Q30: PDL | V30: BTL/KYL
A31: 30 | B31: 21042017 | C31: Mahbub Alam | E31: Active | F31: Pioneer Denim Limited | G31: Finance & Accounts | H31: Executive | I31: 40000 | J31: 8000 | L31: 0.2 | M31: 48000 | Q31: Amount | R31: No's | S31: increment % | T31: Salary Dec'20 | U31: % in Total
A32: 31 | B32: 40312017 | C32: Md. Shahidul Islam | E32: Active | F32: Pioneer Denim Limited | G32: Finance & Accounts | H32: Assistant Manager | I32: 45000 | J32: 8000 | L32: 0.17777778 | M32: 53000 | P32: Marketing | Q32: =SUMIF(G2:N73,P32,J2:J73) -> 116000 | R32: =COUNTIF(G2:G73,P32) -> 19 | S32: =AVERAGEIF(G2:M73,P32,L2:L73) -> 0.19840872 | T32: 1620000 | U32: =Q32/T32 -> 0.071604938
A33: 32 | B33: 40512018 | C33: Mohammad Kamruzzaman Noman | E33: Active | F33: Pioneer Denim Limited | G33: Finance & Accounts | H33: Officer | I33: 30000 | J33: 6000 | L33: 0.2 | M33: 36000 | P33: Finance & Accounts | Q33: =SUMIF(G2:N73,P33,J2:J73) -> 62000 | R33: =COUNTIF(G2:G73,P33) -> 9 | S33: =AVERAGEIF(G2:M73,P33,L2:L73) -> 0.22847122 | T33: 432000 | U33: =Q33/T33 -> 0.14351852
A34: 33 | B34: 40452018 | C34: Md. Mahmudul Hasan | E34: Active | F34: Pioneer Denim Limited | G34: Finance & Accounts | H34: Trainee Officer | I34: 22000 | J34: 5000 | L34: 0.22727273 | M34: 27000 | P34: Audit | Q34: =SUMIF(G2:N73,P34,J2:J73) -> 8000 | R34: =COUNTIF(G2:G73,P34) -> 4 | S34: =AVERAGEIF(G2:M73,P34,L2:L73) -> 0.044444444 | T34: 214000 | U34: =Q34/T34 -> 0.037383178
A35: 34 | B35: 40462018 | C35: Tariqul Islam | E35: Active | F35: Pioneer Denim Limited | G35: Finance & Accounts | H35: Trainee Officer | I35: 15000 | J35: 7000 | L35: 0.46666667 | M35: 22000 | P35: Procurement | Q35: =SUMIF(G2:N73,P35,J2:J73) -> 43000 | R35: =COUNTIF(G2:G73,P35) -> 7 | S35: =AVERAGEIF(G2:M73,P35,L2:L73) -> 0.18954816 | T35: 225000 | U35: =Q35/T35 -> 0.19111111
A36: 35 | B36: 40712019 | C36: Chitta Ranjan Saha | E36: Active | F36: Pioneer Denim Limited | G36: Finance & Accounts | H36: Manager | I36: 80000 | J36: 8000 | L36: 0.1 | M36: 88000 | P36: Commercial | Q36: =SUMIF(G2:N73,P36,J2:J73) -> 86000 | R36: =COUNTIF(G2:G73,P36) -> 14 | S36: =AVERAGEIF(G2:M73,P36,L2:L73) -> 0.30007728 | T36: 386000 | U36: =Q36/T36 -> 0.22279793
A37: 36 | B37: 40822019 | C37: Md. Ashiqur Rahman | E37: Active | F37: Pioneer Denim Limited | G37: Finance & Accounts | H37: Manager | I37: 120000 | J37: 5000 | L37: 0.041666667 | M37: 125000 | P37: Import | Q37: =SUMIF(G2:N73,P37,J2:J73) -> 26000 | R37: =COUNTIF(G2:G73,P37) -> 3 | S37: =AVERAGEIF(G2:M73,P37,L2:L73) -> 0.29589372 | T37: 89000 | U37: =Q37/T37 -> 0.29213483
A38: 37 | B38: 41032020 | C38: Md. Hemaet Ullah | E38: Active | F38: Pioneer Denim Limited | G38: Finance & Accounts | H38: Jr. Officer | I38: 10000 | J38: 5000 | L38: 0.5 | M38: 15000 | P38: Customs | Q38: =SUMIF(G2:N73,P38,J2:J73) -> 15000 | R38: =COUNTIF(G2:G73,P38) -> 2 | S38: =AVERAGEIF(G2:M73,P38,L2:L73) -> 0.16666667 | T38: 90000 | U38: =Q38/T38 -> 0.16666667
A39: 38 | B39: 10252008 | C39: Azmul Karim | E39: Active | F39: Pioneer Denim Limited | G39: Import | H39: Assistant Manager | I39: 46000 | J39: 14000 | L39: 0.30434783 | M39: 60000 | P39: Planning & Coordination | Q39: =SUMIF(G2:N73,P39,J2:J73) -> 17000 | R39: =COUNTIF(G2:G73,P39) -> 3 | S39: =AVERAGEIF(G2:M73,P39,L2:L73) -> 0.098941005 | T39: 190000 | U39: =Q39/T39 -> 0.089473684
A40: 39 | B40: 10702016 | C40: Abdur Rahman | E40: Active | F40: Pioneer Denim Limited | G40: Import | H40: Executive | I40: 28000 | J40: 7000 | L40: 0.25 | M40: 35000 | P40: Costing | Q40: =SUMIF(G2:N73,P40,J2:J73) -> 3000 | R40: =COUNTIF(G2:G73,P40) -> 1 | S40: =AVERAGEIF(G2:M73,P40,L2:L73) -> 0.02 | T40: 192000 | U40: =Q40/T40 -> 0.015625
A41: 40 | B41: 41072020 | C41: Mohammad Tofajjal Hossain | E41: Active | F41: Pioneer Denim Limited | G41: Import | H41: Officer | I41: 15000 | J41: 5000 | L41: 0.33333333 | M41: 20000 | P41: Information Technology | Q41: =SUMIF(G2:N73,P41,J2:J73) -> 0 | R41: =COUNTIF(G2:G73,P41) -> 3 | S41: =AVERAGEIF(G2:M73,P41,L2:L73) -> 0 | T41: 155000 | U41: =Q41/T41 -> 0
A42: 41 | B42: 10102012 | C42: Md. Tyoubur Rahman | E42: Active | F42: Pioneer Denim Limited | G42: Information Technology | H42: Head of IT | I42: 70000 | J42: 0 | L42: 0 | M42: 70000 | P42: Administration | Q42: =SUMIF(G2:N73,P42,J2:J73) -> 15000 | R42: =COUNTIF(G2:G73,P42) -> 7 | S42: =AVERAGEIF(G2:M73,P42,L2:L73) -> 0.16020408 | T42: 71000 | U42: =Q42/T42 -> 0.21126761
A43: 42 | B43: 41142020 | C43: Md. Ashraful Alam | E43: Active | F43: Pioneer Denim Limited | G43: Information Technology | H43: Software Engineer | I43: 40000 | J43: 0 | L43: 0 | M43: 40000 | Q43: =SUM(Q32:Q42) -> 391000 | R43: =SUM(R32:R42) -> 72 | S43: =AVERAGE(S32:S42) -> 0.15478685 | T43: =SUM(T32:T42) -> 3664000
A44: 43 | B44: 41152020 | C44: Md. Hasan Uzzaman | E44: Active | F44: Pioneer Denim Limited | G44: Information Technology | H44: Software Engineer | I44: 45000 | J44: 0 | L44: 0 | M44: 45000 | Q44: =Q43/T43 -> 0.10671397
A45: 44 | B45: 40362018 | C45: Md. Hasibul Huda | E45: Active | F45: Pioneer Denim Limited | G45: Marketing | H45: Deputy General Manager | I45: 350000 | J45: 10000 | L45: 0.028571429 | M45: 360000
A46: 45 | B46: 40052018 | C46: Atekur Rahman Nayim | E46: Active | F46: Pioneer Denim Limited | G46: Marketing | H46: RM | I46: 68000 | J46: 32000 | L46: 0.47058824 | M46: 100000 | N46: AI: 0, SP: 32k
A47: 46 | B47: 40372018 | C47: Gazi Fayshal Ahmed | E47: Active | F47: Pioneer Denim Limited | G47: Marketing | H47: JRM | I47: 30000 | J47: 5000 | L47: 0.16666667 | M47: 35000
A48: 47 | B48: 40432018 | C48: Md. Zahidur Rahman | E48: Active | F48: Pioneer Denim Limited | G48: Marketing | H48: ARM | I48: 50000 | J48: 13000 | L48: 0.26 | M48: 63000
A49: 48 | B49: 40592019 | C49: Abrar Rahman Siam | E49: Active | F49: Pioneer Denim Limited | G49: Marketing | H49: JRM | I49: 25000 | J49: 5000 | L49: 0.2 | M49: 30000
A50: 49 | B50: 40652019 | C50: Md. Arafat Hossain | E50: Active | F50: Pioneer Denim Limited | G50: Marketing | H50: ARM | I50: 55000 | J50: 7000 | L50: 0.12727273 | M50: 62000
A51: 50 | B51: 41052020 | C51: Muhammad Zakir Hossain | E51: Active | F51: Pioneer Denim Limited | G51: Marketing | H51: Deputy General Manager | I51: 300000 | J51: 0 | L51: 0 | M51: 300000
A52: 51 | B52: 41102020 | C52: Md. Johan Islam | E52: Active | F52: Pioneer Denim Limited | G52: Marketing | H52: ARM | I52: 70000 | J52: 0 | L52: 0 | M52: 70000
A53: 52 | B53: 40772019 | C53: Md. Emran Hossain Khan | E53: Active | F53: Pioneer Denim Limited | G53: Marketing | H53: JRM | I53: 15000 | J53: 7000 | L53: 0.46666667 | M53: 22000
A54: 53 | B54: 40922020 | C54: Md. Syed Mizanul Huq | E54: Active | F54: Pioneer Denim Limited | G54: Marketing | H54: Trainee Officer | I54: 15000 | J54: 7000 | L54: 0.46666667 | M54: 22000
A55: 54 | B55: 41172020 | C55: Asif Wares Khan | E55: Active | F55: Pioneer Denim Limited | G55: Marketing | H55: RM | I55: 125000 | J55: 0 | L55: 0 | M55: 125000
...

Sheet 2019_PDL
A1: SL | B1: ID | C1: Name | D1: DOJ | E1: Emp_Status | F1: Business_Unit_18 | G1: Department_18 | H1: Position_18 | I1: Previous Salary_18 | J1: Increment_18 | K1: Promotion_18 | L1: Perc_18 | M1: Salary_18 | N1: Remarks_18
B2: 10062011 | C2: Md. Kamruzzaman | E2: Active | F2: BTL/KYL | G2: Marketing & Sales | H2: Head of Marketing & Sales | I2: 102000 | J2: 48000 | L2: 0.47058824 | M2: 150000 | N2: AE: 25k, SP: 23k
B3: 20042012 | C3: Mohammed Nurul Akter Chowdhury | E3: Active | F3: BTL/KYL | G3: Marketing & Sales | H3: Head of Marketing (Rotor) | I3: 100000 | J3: 20000 | L3: 0.2 | M3: 120000
B4: 10042008 | C4: Liton Apu Biswas | E4: Active | F4: BTL/KYL | G4: Marketing & Sales | H4: Head of Marketing (North Zone) | I4: 100000 | J4: 20000 | L4: 0.2 | M4: 120000
B5: 10052012 | C5: Md. Abdul Maleque | E5: Active | F5: BTL/KYL | G5: Marketing & Sales | H5: Head of Marketing (Middle Zone) | I5: 90000 | J5: 20000 | L5: 0.22222222 | M5: 110000
B6: 20532015 | C6: Md. Mahmudul Alam Chapol | E6: Active | F6: BTL/KYL | G6: Marketing & Sales | H6: Assistant Manager | I6: 60000 | J6: 10000 | L6: 0.16666667 | M6: 70000
B7: 21072016 | C7: Md. Alamgir Mia | E7: Active | F7: BTL/KYL | G7: Marketing & Sales | H7: Assistant Manager | I7: 54000 | J7: 4000 | L7: 0.074074074 | M7: 58000
B8: 10132009 | C8: Ahsan Shiblee | E8: Active | F8: BTL/KYL | G8: Marketing & Sales | H8: Assistant Manager | I8: 45000 | J8: 5000 | L8: 0.11111111 | M8: 50000
B9: 10582007 | C9: Md. Mahabubur Rahman | E9: Active | F9: BTL/KYL | G9: Marketing & Sales | H9: ? | I9: 35000 | J9: 0 | L9: 0 | M9: 35000
B10: 10782016 | C10: Mohammad Kawsar Molla | E10: Active | F10: BTL/KYL | G10: Finance & Accounts | H10: Head of Finance & Accounts | I10: 180000 | J10: 5000 | L10: 0.027777778 | M10: 185000
B11: 21152017 | C11: Mir Muhshiuzzaman | E11: Active | F11: BTL/KYL | G11: Finance & Accounts | H11: Manager | I11: 105000 | J11: 5000 | L11: 0.047619048 | M11: 110000
B12: 20332017 | C12: Moniruzzaman | E12: Active | F12: BTL/KYL | G12: Finance & Accounts | H12: Assistant Manager | I12: 67000 | J12: 3000 | L12: 0.044776119 | M12: 70000
B13: 20342009 | C13: Mohammad Shawkot Alam | E13: Active | F13: BTL/KYL | G13: Finance & Accounts | H13: Senior Executive | I13: 47000 | J13: 3000 | L13: 0.063829787 | M13: 50000
B14: 10752016 | C14: Md. Sharforaz Hossain | E14: Active | F14: BTL/KYL | G14: Finance & Accounts | H14: Executive | I14: 35000 | J14: 5000 | L14: 0.14285714 | M14: 40000
... B43: 20072000 | C43: Rakibul Hasan Chowdhury | E43: Active | F43: BTL/KYL | G43: Commercial | H43: Incharge | I43: 55000 | J43: 4000 | L43: 0.072727273 | M43: 59000
B44: 20122009 | C44: Syed Mahmood Hassan | E44: Active | F44: BTL/KYL | G44: Commercial | H44: Jr. Officer | I44: 35000 | J44: 6000 | L44: 0.17142857 | M44: 41000 | N44: AI: 3k, SP: 3k
B45: 21142017 | C45: Sohebul Islam | E45: Active | F45: BTL/KYL | G45: Commercial | H45: Jr. Officer | I45: 22000 | J45: 5000 | L45: 0.22727273 | M45: 27000
B46: 10542014 | C46: Md. Foysal Hassan | E46: Active | F46: BTL/KYL | G46: Commercial | H46: Executive | I46: 25000 | J46: 4000 | L46: 0.16 | M46: 29000
B47: 10192011 | C47: Md. Kamal Ahmed | E47: Active | F47: BTL/KYL | G47: Commercial | H47: Jr. Officer | I47: 27000 | J47: 5000 | L47: 0.18518519 | M47: 32000
B48: 20062000 | C48: Asraful Islam | E48: Active | F48: BTL/KYL | G48: Commercial | H48: Incharge | I48: 63000 | J48: 5000 | L48: 0.079365079 | M48: 68000
B49: 10112004 | C49: Mohmmad Omar Faruque | E49: Active | F49: BTL/KYL | G49: Commercial | H49: Executive | I49: 35000 | J49: 5000 | L49: 0.14285714 | M49: 40000
B50: 20172012 | C50: Md. Al-Amin Khan | E50: Active | F50: BTL/KYL | G50: Legal & Estate | H50: Executive | I50: 26000 | J50: 4000 | L50: 0.15384615 | M50: 30000
B51: 21312018 | C51: Muhammad Milon Hossain Molla | E51: Active | F51: BTL/KYL | G51: Commercial | H51: ? | I51: 14000 | J51: 6000 | L51: 0.42857143 | M51: 20000
B52: 10202011 | C52: Muhammad Momin Hossen | E52: Active | F52: BTL/KYL | G52: Commercial | H52: Executive | I52: 22000 | J52: 3000 | L52: 0.13636364 | M52: 25000
B53: 10212011 | C53: Md. Shakamal | E53: Active | F53: BTL/KYL | G53: Commercial | H53: ? | I53: 22000 | J53: 5000 | L53: 0.22727273 | M53: 27000
B54: 10222012 | C54: Ashiqur Rahman Robin | E54: Active | F54: BTL/KYL | G54: Commerical | H54: ? | I54: 22000 | J54: 8000 | L54: 0.36363636 | M54: 30000
B55: 10522014 | C55: Arshadul Haque Molla | E55: Active | F55: BTL/KYL | G55: Commercial | H55: ? | I55: 20000 | J55: 3000 | L55: 0.15 | M55: 23000
B56: 20892017 | C56: Mahamudun Nabi Ove | E56: Active | F56: BTL/KYL | G56: Commercial | H56: Jr. Executive | I56: 15000 | J56: 5000 | L56: 0.33333333 | M56: 20000
... B97: 21422018 | C97: Md. Karimul | E97: Active | F97: BTL/KYL | G97: Administration | H97: Lift Man | I97: 14000 | J97: 2000 | L97: 0.14285714 | M97: 16000
B98: 21392018 | C98: Md. Mehedi Hasan | E98: Active | F98: BTL/KYL | G98: Administration | H98: Peon | I98: 10000 | J98: 4000 | L98: 0.4 | M98: 14000 | N98: As per Grading
B99: 21382018 | C99: Md. Jamal Hossain | E99: Active | F99: BTL/KYL | G99: Administration | H99: Peon | I99: 10000 | J99: 2000 | L99: 0.2 | M99: 12000
B100: 21512019 | C100: Nasima | E100: Active | F100: BTL/KYL | G100: Administration | H100: Asst. Cook | I100: 9000 | J100: 1000 | L100: 0.11111111 | M100: 10000
B101: 21412018 | C101: Md. Masud Rana | E101: Active | F101: BTL/KYL | G101: Administration | H101: Asst. Cook | I101: 10000 | J101: 3000 | L101: 0.3 | M101: 13000
B102: 21252018 | C102: Md. Shazib Madbar | E102: Active | F102: BTL/KYL | G102: Transport | H102: Driver | I102: 18000 | J102: 1000 | L102: 0.055555556 | M102: 19000 | N102: Grade A
B103: 20522011 | C103: Md. Lokman Hossain | E103: Active | F103: BTL/KYL | G103: Transport | H103: Driver | I103: 17000 | J103: 2000 | L103: 0.11764706 | M103: 19000 | N103: Grade A
B104: 21242018 | C104: Md. Rubel | E104: Active | F104: BTL/KYL | G104: Transport | H104: Driver | I104: 17000 | J104: 2000 | L104: 0.11764706 | M104: 19000 | N104: Grade A
B105: 10612015 | C105: Md. Abu Hanif | E105: Active | F105: BTL/KYL | G105: Transport | H105: Driver | I105: 17000 | J105: 2000 | L105: 0.11764706 | M105: 19000 | N105: Grade A
B106: 11152018 | C106: Md. Asaduzzaman Fakir | E106: Active | F106: BTL/KYL | G106: Transport | H106: Driver | I106: 17000 | J106: 1000 | L106: 0.058823529 | M106: 18000 | N106: Grade B
B107: 11282018 | C107: Md. Shahjada Bhuiyan | E107: Active | F107: BTL/KYL | G107: Audit | H107: Assistant Manager | I107: 42000 | J107: 0 | L107: 0 | M107: 42000
B108: 21452019 | C108: Md. Masum Billah | E108: Active | F108: BTL/KYL | G108: Audit | H108: Audit Assistant | I108: 14000 | J108: 2000 | L108: 0.14285714 | M108: 16000
...

Sheet 2017
A1: SL | B1: ID | C1: Name | D1: DOJ | E1: Increment_16 | F1: Emp_Status | G1: Business_Unit_17 | H1: Department_17 | I1: Position_17 | J1: Increment_17 | K1: Promotion_17 | L1: Salary_17 | M1: Remarks_17
B2: 10062011 | C2: Md. Kamruzzaman | E2: 9000 | F2: Active | G2: BTL/KYL | H2: Marketing & Sales | I2: Manager | J2: 10000 | L2: 102000
B3: 20042012 | C3: Mohammed Nurul Akter Chowdhury | E3: 5000 | F3: Active | G3: BTL/KYL | H3: Marketing & Sales | I3: Manager | J3: 10000 | L3: 100000
B4: 10042008 | C4: Liton Apu Biswas | E4: 3000 | F4: Active | G4: BTL/KYL | H4: Marketing & Sales | I4: Manager | J4: 10000 | L4: 100000
B5: 10052012 | C5: Md. Abdul Maleque | E5: 10000 | F5: Active | G5: BTL/KYL | H5: Marketing & Sales | I5: Manager | J5: 10000 | L5: 90000
B6: 20532015 | C6: Md. Mahmudul Alam Chapol | E6: 5000 | F6: Active | G6: BTL/KYL | H6: Marketing & Sales | I6: Assistant Manager | J6: 5000 | L6: 60000
B7: 21072016 | C7: Md. Alamgir Mia | E7: 0 | F7: Active | G7: BTL/KYL | H7: Marketing & Sales | I7: Assistant Manager | L7: 54000
B8: 10132009 | C8: Ahsan Shiblee | E8: 4000 | F8: Active | G8: BTL/KYL | H8: Marketing & Sales | I8: Assistant Manager | J8: 5000 | L8: 45000
B9: 20092008 | C9: Khandker Mustafizur Rahman | E9: 7000 | F9: Active | G9: BTL/KYL | H9: Marketing & Sales | I9: Assistant Manager | J9: 7000 | L9: 62000
B10: 10582007 | C10: Md. Mahabubur Rahman | E10: 2000 | F10: Active | G10: BTL/KYL | H10: Marketing & Sales | I10: Assistant Manager | J10: 3000 | L10: 35000
B11: 10782016 | C11: Mohammad Kawsar Molla | E11: 0 | F11: Active | G11: BTL/KYL | H11: Finance & Accounts | I11: Head of Finance & Accounts | J11: 0 | L11: 180000
B12: 21152017 | C12: Mir Muhshiuzzaman | E12: 0 | F12: Active | G12: BTL/KYL | H12: Finance & Accounts | I12: Manager | J12: 5000 | L12: 105000
B13: 20332017 | C13: Moniruzzaman | E13: 0 | F13: Active | G13: BTL/KYL | H13: Finance & Accounts | I13: Assistant Manager | J13: 7000 | L13: 67000
B14: 20342009 | C14: Mohammad Shawkot Alam | E14: 4000 | F14: Active | G14: BTL/KYL | H14: Finance & Accounts | I14: Executive | J14: 3000 | K14: Sr. Executive | L14: 47000
B15: 10752016 | C15: Md. Sharforaz Hossain | E15: 0 | F15: Active | G15: BTL/KYL | H15: Finance & Accounts | I15: Officer | J15: 7000 | K15: Executive | L15: 35000
B16: 10732016 | C16: Md. Bablu | E16: 0 | F16: Active | G16: BTL/KYL | H16: Finance & Accounts | I16: Officer | J16: 7000 | K16: Executive | L16: 33000
B17: 20302005 | C17: Md. Ruhul Amin | E17: 1000 | F17: Active | G17: BTL/KYL | H17: Finance & Accounts | I17: Executive | J17: 2000 | L17: 46000
B18: 10392012 | C18: Md. Abdul Motin | E18: 1000 | F18: Active | G18: BTL/KYL | H18: Finance & Accounts | I18: Jr. Officer | J18: 3000 | K18: Officer | L18: 33000
B19: 10402012 | C19: Md. Rofiqul Islam | E19: 3000 | F19: Active | G19: BTL/KYL | H19: Finance & Accounts | I19: Jr. Executive | J19: 4000 | K19: Officer | L19: 36000
B20: 10722016 | C20: Muhammad Masum Billah | E20: 3000 | F20: Active | G20: BTL/KYL | H20: Finance & Accounts | I20: Jr. Officer | J20: 3000 | L20: 30000
B21: 10692016 | C21: Md. Oaliullah | E21: 5000 | F21: Active | G21: BTL/KYL | H21: Finance & Accounts | I21: Executive | J21: 6000 | L21: 26000
B22: 20932017 | C22: Md. Humayun Kabir | E22: 0 | F22: Active | G22: BTL/KYL | H22: Finance & Accounts | I22: Executive | J22: 5000 | L22: 25000 | M22: Special 5,000
B23: 20992017 | C23: Mostafizur Rahman | E23: 8000 | F23: Active | G23: BTL/KYL | H23: Finance & Accounts | I23: Trainee Officer | J23: 3000 | K23: Jr. Officer | L23: 23000
B24: 21212018 | C24: Md. Shahadat Hossain | E24: 0 | F24: Active | G24: BTL/KYL | H24: Finance & Accounts | I24: Trainee Officer | J24: 2000 | L24: 20000 | M24: Special 3,000
B25: 21322018 | C25: Md. Ridoy Masud Bhuiyan | F25: Active | G25: BTL/KYL | H25: Finance & Accounts | I25: Officer | J25: 2000 | K25: - | L25: 18000 | M25: Special 3,000
B26: 11012018 | C26: Mohammad Kabir Hossain | E26: 0 | F26: Active | G26: BTL/KYL | H26: Audit | I26: Head of Audit | J26: 0 | L26: 150000
B27: 20282010 | C27: Md. Mehedi Hasan | E27: 0 | F27: Active | G27: BTL/KYL | H27: Audit | I27: Sr. Executive | J27: 5000 | L27: 61000
B28: 21132017 | C28: Md. Moniruzzaman | E28: 0 | F28: Active | G28: BTL/KYL | H28: Audit | I28: Sr. Executive | J28: 5000 | L28: 45000
B29: 30572016 | C29: Md. Abdus Sabur Talukder | E29: 0 | F29: Active | G29: BTL/KYL | H29: Audit | I29: Sr. Officer | J29: 4000 | L29: 30000
B30: 20982017 | C30: Gobinda Chandra Dey | E30: 5000 | F30: Active | G30: BTL/KYL | H30: Audit | I30: Executive | J30: 5000 | L30: 40000
B31: 10712016 | C31: Md. Amin Ullah | E31: 7000 | F31: Active | G31: BTL/KYL | H31: Export Import Audit | I31: Executive | J31: 7000 | L31: 42000
B32: 20352011 | C32: Md. Safiul Muznabin | E32: 1000 | F32: Active | G32: BTL/KYL | H32: Export Import Audit | I32: Jr. Officer | J32: 3000 | L32: 33000
B33: 21232018 | C33: Md. Shafiqul Islam | E33: 0 | F33: Active | G33: BTL/KYL | H33: Export Import Audit | I33: Trainee Officer | J33: 3000 | L33: 20000
B34: 20842017 | C34: Yousuf Ahmmed | E34: 4000 | F34: Active | G34: BTL/KYL | H34: Export Import Audit | I34: Officer | J34: 7000 | L34: 25000
B35: 11092018 | C35: Mosharraf Hossain Chowdhury (Faisal) | E35: 0 | F35: Inactive | G35: Inactive | H35: Inactive | I35: Inactive | J35: 0 | K35: Inactive | L35: 0 | M35: Inactive
